Workbook

Sheet Assessment sheet (ES)
A1: Lakshmi Narain College of Technology & Science , Bhopal
A2: Record of End Sem Marks
A3: Year/Semester: II/IV | C3: Branch/Section: CSE-/ A | F3: Session: JAN-JUNE. 2025
A4: Subject Code & Name: CS403 & Software Engg.
A5: Class Roll No. | B5: Student Name | C5: Enrollment No. | D5: End Sem (Th) | F5: End Sem (P)
D6: (70) | F6: (30)
D7: Grade | E7: Avg. Marks (100) | F7: Grade | G7: Avg. Marks (30)
D8: 10 | E8: 10 | F8: 10 | G8: 10
A9: 001 | B9: Aarchi Porwal | C9: 0157CS231001
A10: 002 | B10: Aarti Pawar | C10: 0157CS231002
A11: 003 | B11: Aatifa Firdous Ashrafi | C11: 0157CS231003
A12: 004 | B12: Aayushi Gaur | C12: 0157CS231004
A13: 005 | B13: Abhay Agrawal | C13: 0157CS231005
A14: 006 | B14: Abhay Arya | C14: 0157CS231006
A15: 007 | B15: Abhay Kumar Sharma | C15: 0157CS231007
A16: 008 | B16: Abhay Raj | C16: 0157CS231008
A17: 009 | B17: Abhi Jain | C17: 0157CS231009
A18: 010 | B18: Abhijeet Batania | C18: 0157CS231010
A19: 011 | B19: Abhijeet Singh Jadaun | C19: 0157CS231011
A20: 012 | B20: Abhinav Adlak | C20: 0157CS231012
... A92: 084 | B92: Harshdeep Jain | C92: 0157CS231084

Sheet Assessment sheet (MST)
A1: Lakshmi Narain College of Technology & Science , Bhopal
A2: Record of Assessment of Mid-Sem Test
A3: ='Assessment sheet (ES)'!A3:B3 -> Year/Semester: II/IV | C3: ='Assessment sheet (ES)'!C3:D3 -> Branch/Section: CSE-/ A | F3: ='Assessment sheet (ES)'!F3:G3 -> Session: JAN-JUNE. 2025
A4: ='Assessment sheet (ES)'!A4:C4 -> Subject Code & Name: CS403 & Software Engg.
A5: Class Roll No. | B5: FirstName | C5: Enrollment No. | D5: Mid Sem Exam.
D6: (20)
D7: CO1 | E7: CO2 | F7: CO3 | G7: CO4 | H7: CO5
D8: 10 | E8: 10 | F8: 7 | G8: 7 | H8: 6
A9: 001 | B9: Aarchi Porwal | C9: 0157CS231001 | D9: 10 | E9: 9 | F9: 0 | G9: 0 | H9: 0
A10: 002 | B10: Aarti Pawar | C10: 0157CS231002 | D10: 8 | E10: 7 | F10: 0 | G10: 0 | H10: 0
A11: 003 | B11: Aatifa Firdous Ashrafi | C11: 0157CS231003 | D11: 9 | E11: 9 | F11: 0 | G11: 0 | H11: 0
A12: 004 | B12: Aayushi Gaur | C12: 0157CS231004 | D12: 0 | E12: 0 | F12: 6 | G12: 7 | H12: 6
A13: 005 | B13: Abhay Agrawal | C13: 0157CS231005 | D13: 7 | E13: 6 | F13: 7 | G13: 7 | H13: 5
A14: 006 | B14: Abhay Arya | C14: 0157CS231006 | D14: 8 | E14: 8 | F14: 0 | G14: 0 | H14: 0
A15: 007 | B15: Abhay Kumar Sharma | C15: 0157CS231007 | D15: 9 | E15: 3 | F15: 7 | G15: 7 | H15: 5
A16: 008 | B16: Abhay Raj | C16: 0157CS231008 | D16: 5 | E16: 7 | F16: 6 | G16: 6 | H16: 5
A17: 009 | B17: Abhi Jain | C17: 0157CS231009 | D17: 9 | E17: 10 | F17: 0 | G17: 0 | H17: 0
A18: 010 | B18: Abhijeet Batania | C18: 0157CS231010 | D18: 10 | E18: 10 | F18: 0 | G18: 0 | H18: 0
A19: 011 | B19: Abhijeet Singh Jadaun | C19: 0157CS231011 | D19: 9 | E19: 9 | F19: 0 | G19: 0 | H19: 0
A20: 012 | B20: Abhinav Adlak | C20: 0157CS231012 | D20: 8 | E20: 8 | F20: 0 | G20: 0 | H20: 0
... A92: 084 | B92: Harshdeep Jain | C92: 0157CS231084 | D92: 7 | E92: 6 | F92: 7 | G92: 6 | H92: 5

Sheet (F) Assessment sheet (QA)
A1: Lakshmi Narain College of Technology & Science , Bhopal
A2: Record of Assessment of Quiz/Assignment
A3: ='Assessment sheet (ES)'!A3:B3 -> Year/Semester: II/IV | C3: ='Assessment sheet (ES)'!C3:D3 -> Branch/Section: CSE-/ A | F3: ='Assessment sheet (ES)'!F3:G3 -> Session: JAN-JUNE. 2025
A4: ='Assessment sheet (ES)'!A4:C4 -> Subject Code & Name: CS403 & Software Engg.
A5: Class Roll No. | B5: FirstName | C5: Enrollment No. | D5: Quiz/Assignment (Th)
D6: (10)
D7: CO1 | E7: CO2 | F7: CO3 | G7: CO4 | H7: CO5
D8: 10 | E8: 10 | F8: 10 | G8: 10 | H8: 10
A9: 001 | B9: Aarchi Porwal | C9: 0157CS231001 | D9: 10 | E9: 10 | F9: 10 | G9: 10 | H9: 10 | I9: =D9+E9+F9+G9+H9 -> 50 | K9: =L9-I9 -> 0 | L9: =M9*5 -> 50 | M9: =F9+K9 -> 9
A10: 002 | B10: Aarti Pawar | C10: 0157CS231002 | D10: 9 | E10: 9 | F10: 9 | G10: 9 | H10: 9 | I10: =D10+E10+F10+G10+H10 -> 45 | K10: =L10-I10 -> 0 | L10: =M10*5 -> 50 | M10: =F10+K10 -> 10
A11: 003 | B11: Aatifa Firdous Ashrafi | C11: 0157CS231003 | D11: 8 | E11: 7 | F11: 8 | G11: 8 | H11: 8 | I11: =D11+E11+F11+G11+H11 -> 39 | K11: =L11-I11 -> 0 | L11: =M11*5 -> 50 | M11: =F11+K11 -> 10
A12: 004 | B12: Aayushi Gaur | C12: 0157CS231004 | D12: 8 | E12: 8 | F12: 8 | G12: 8 | H12: 8 | I12: =D12+E12+F12+G12+H12 -> 40 | K12: =L12-I12 -> 0 | L12: =M12*5 -> 50 | M12: =F12+K12 -> 9
A13: 005 | B13: Abhay Agrawal | C13: 0157CS231005 | D13: 7 | E13: 7 | F13: 7 | G13: 7 | H13: 7 | I13: =D13+E13+F13+G13+H13 -> 35 | K13: =L13-I13 -> 0 | L13: =M13*5 -> 50 | M13: =F13+K13 -> 10
A14: 006 | B14: Abhay Arya | C14: 0157CS231006 | D14: 8 | E14: 8 | F14: 8 | G14: 8 | H14: 8 | I14: =D14+E14+F14+G14+H14 -> 40 | K14: =L14-I14 -> 0 | L14: =M14*5 -> 50 | M14: =F14+K14 -> 10
A15: 007 | B15: Abhay Kumar Sharma | C15: 0157CS231007 | D15: 9 | E15: 9 | F15: 9 | G15: 9 | H15: 9 | I15: =D15+E15+F15+G15+H15 -> 45 | K15: =L15-I15 -> 0 | L15: =M15*5 -> 50 | M15: =F15+K15 -> 10
A16: 008 | B16: Abhay Raj | C16: 0157CS231008 | D16: 9 | E16: 9 | F16: 9 | G16: 9 | H16: 9 | I16: =D16+E16+F16+G16+H16 -> 45 | K16: =L16-I16 -> 0 | L16: =M16*5 -> 50 | M16: =F16+K16 -> 9
A17: 009 | B17: Abhi Jain | C17: 0157CS231009 | D17: 7 | E17: 7 | F17: 7 | G17: 7 | H17: 7 | I17: =D17+E17+F17+G17+H17 -> 35 | K17: =L17-I17 -> 0 | L17: =M17*5 -> 50 | M17: =F17+K17 -> 10
A18: 010 | B18: Abhijeet Batania | C18: 0157CS231010 | D18: 9 | E18: 9 | F18: 9 | G18: 9 | H18: 9 | I18: =D18+E18+F18+G18+H18 -> 45 | K18: =L18-I18 -> 0 | L18: =M18*5 -> 50 | M18: =F18+K18 -> 10
A19: 011 | B19: Abhijeet Singh Jadaun | C19: 0157CS231011 | D19: 8 | E19: 8 | F19: 8 | G19: 8 | H19: 8 | I19: =D19+E19+F19+G19+H19 -> 40 | K19: =L19-I19 -> 0 | L19: =M19*5 -> 50 | M19: =F19+K19 -> 10
A20: 012 | B20: Abhinav Adlak | C20: 0157CS231012 | D20: 8 | E20: 8 | F20: 8 | G20: 8 | H20: 8 | I20: =D20+E20+F20+G20+H20 -> 40 | K20: =L20-I20 -> 0 | L20: =M20*5 -> 50 | M20: =F20+K20 -> 10
... A87: 079 | B87: Gouransh Kumar Bain | C87: 0157CS231079 | D87: 4 | E87: 4 | F87: 4 | G87: 4 | H87: 4 | I87: =D87+E87+F87+G87+H87 -> 20 | K87: =L87-I87 -> 0 | L87: =M87*5 -> 50 | M87: =F87+K87 -> 4
A88: 080 | B88: Harsh Chouksey | C88: 0157CS231080 | D88: 9 | E88: 9 | F88: 9 | G88: 9 | H88: 8 | I88: =D88+E88+F88+G88+H88 -> 44 | L88: =M88*5 -> 45 | M88: 9
A89: 081 | B89: Harsh Raj Kourav | C89: 0157CS231081 | D89: 8 | E89: 8 | F89: 8 | G89: 7 | H89: 6 | I89: =D89+E89+F89+G89+H89 -> 37 | L89: =M89*5 -> 40 | M89: 8
A90: 082 | B90: Harsh Tiwari | C90: 0157CS231082 | D90: 8 | E90: 9 | F90: 9 | G90: 9 | H90: 9 | L90: =M90*5 -> 45 | M90: 9
A91: 083 | B91: Harsh Kanojiya | C91: 0157CS231083 | D91: 9 | E91: 9 | F91: 9 | G91: 9 | H91: 8 | L91: =M91*5 -> 45 | M91: 9
A92: 084 | B92: Harshdeep Jain | C92: 0157CS231084 | D92: 10 | E92: 10 | F92: 10 | G92: 10 | H92: 10 | L92: =M92*5 -> 50 | M92: 10

Sheet Assessment sheet (LWS)
A1: Lakshmi Narain College of Technology & Science , Bhopal
A2: Record of Assessment of Lab Work/Sessional
A3: ='Assessment sheet (ES)'!A3:B3 -> Year/Semester: II/IV | C3: ='Assessment sheet (ES)'!C3:D3 -> Branch/Section: CSE-/ A | F3: ='Assessment sheet (ES)'!F3:G3 -> Session: JAN-JUNE. 2025
A4: ='Assessment sheet (ES)'!A4:C4 -> Subject Code & Name: CS403 & Software Engg.
A5: Class Roll No. | B5: First Name | C5: Enrollment No. | D5: Lab Work & Sessional (P)
D6: (20)
D7: CO1 | E7: CO2 | F7: CO3 | G7: CO4 | H7: CO5 | J7: 7
D8: 10 | E8: 10 | F8: 10 | G8: 10 | H8: 10
A9: 001 | B9: Aarchi Porwal | C9: 0157CS231001 | D9: 8 | E9: 9 | F9: 9 | G9: 9 | H9: 7 | J9: =D9+E9+F9+G9+H9 -> 42 | K9: =L9-J9 -> 0.5 | L9: =N9*2.5 -> 42.5 | N9: 17
A10: 002 | B10: Aarti Pawar | C10: 0157CS231002 | D10: 10 | E10: 10 | F10: 10 | G10: 10 | H10: 10 | J10: =D10+E10+F10+G10+H10 -> 50 | K10: =L10-J10 -> 0 | L10: =N10*2.5 -> 50 | N10: 20
A11: 003 | B11: Aatifa Firdous Ashrafi | C11: 0157CS231003 | D11: 10 | E11: 10 | F11: 10 | G11: 10 | H11: 10 | J11: =D11+E11+F11+G11+H11 -> 50 | K11: =L11-J11 -> 0 | L11: =N11*2.5 -> 50 | N11: 20
A12: 004 | B12: Aayushi Gaur | C12: 0157CS231004 | D12: 8 | E12: 9 | F12: 9 | G12: 9 | H12: 7 | J12: =D12+E12+F12+G12+H12 -> 42 | K12: =L12-J12 -> 0.5 | L12: =N12*2.5 -> 42.5 | N12: 17
A13: 005 | B13: Abhay Agrawal | C13: 0157CS231005 | D13: 10 | E13: 10 | F13: 10 | G13: 10 | H13: 10 | J13: =D13+E13+F13+G13+H13 -> 50 | K13: =L13-J13 -> 0 | L13: =N13*2.5 -> 50 | N13: 20
A14: 006 | B14: Abhay Arya | C14: 0157CS231006 | D14: 10 | E14: 10 | F14: 10 | G14: 10 | H14: 10 | J14: =D14+E14+F14+G14+H14 -> 50 | K14: =L14-J14 -> 0 | L14: =N14*2.5 -> 50 | N14: 20
A15: 007 | B15: Abhay Kumar Sharma | C15: 0157CS231007 | D15: 10 | E15: 10 | F15: 10 | G15: 10 | H15: 10 | J15: =D15+E15+F15+G15+H15 -> 50 | K15: =L15-J15 -> 0 | L15: =N15*2.5 -> 50 | N15: 20
A16: 008 | B16: Abhay Raj | C16: 0157CS231008 | D16: 8 | E16: 9 | F16: 9 | G16: 9 | H16: 7 | J16: =D16+E16+F16+G16+H16 -> 42 | K16: =L16-J16 -> 0.5 | L16: =N16*2.5 -> 42.5 | N16: 17
A17: 009 | B17: Abhi Jain | C17: 0157CS231009 | D17: 10 | E17: 10 | F17: 10 | G17: 10 | H17: 10 | J17: =D17+E17+F17+G17+H17 -> 50 | K17: =L17-J17 -> 0 | L17: =N17*2.5 -> 50 | N17: 20
A18: 010 | B18: Abhijeet Batania | C18: 0157CS231010 | D18: 10 | E18: 10 | F18: 10 | G18: 10 | H18: 10 | J18: =D18+E18+F18+G18+H18 -> 50 | K18: =L18-J18 -> 0 | L18: =N18*2.5 -> 50 | N18: 20
A19: 011 | B19: Abhijeet Singh Jadaun | C19: 0157CS231011 | D19: 10 | E19: 10 | F19: 10 | G19: 10 | H19: 10 | J19: =D19+E19+F19+G19+H19 -> 50 | K19: =L19-J19 -> 0 | L19: =N19*2.5 -> 50 | N19: 20
A20: 012 | B20: Abhinav Adlak | C20: 0157CS231012 | D20: 10 | E20: 10 | F20: 10 | G20: 10 | H20: 10 | J20: =D20+E20+F20+G20+H20 -> 50 | K20: =L20-J20 -> 0 | L20: =N20*2.5 -> 50 | N20: 20
... A75: 067 | B75: Devanshu Kushwah | C75: 0157CS231067 | D75: 8 | E75: 9 | F75: 9 | G75: 9 | H75: 7 | J75: =D75+E75+F75+G75+H75 -> 42 | K75: =L75-J75 -> 0.5 | L75: =N75*2.5 -> 42.5 | N75: 17
